Workbook

Sheet INDEX
A1: node_id | B1: category | C1: bestsellers_url | D1: listed_rows
A2: 11056291 | B2: Body Washes | C2: https://www.amazon.com/Best-Sellers/zgbs/beauty/11056291 | D2: =COUNT('Body Washes'!A:A)
A3: 11060451 | B3: Skin Care | C3: https://www.amazon.com/Best-Sellers/zgbs/beauty/11060451 | D3: =COUNT('Skin Care'!A:A)
A4: 11060521 | B4: Body | C4: https://www.amazon.com/Best-Sellers/zgbs/beauty/11060521 | D4: =COUNT('Body'!A:A)
A5: 11060661 | B5: Moisturizers | C5: https://www.amazon.com/Best-Sellers/zgbs/beauty/11060661 | D5: =COUNT('Moisturizers'!A:A)
A6: 11060711 | B6: Face | C6: https://www.amazon.com/Best-Sellers/zgbs/beauty/11060711 | D6: =COUNT('Face'!A:A)
A7: 11061941 | B7: Eyes | C7: https://www.amazon.com/Best-Sellers/zgbs/beauty/11061941 | D7: =COUNT('Eyes'!A:A)
A8: 11062651 | B8: Sunscreens | C8: https://www.amazon.com/Best-Sellers/zgbs/beauty/11062651 | D8: =COUNT('Sunscreens'!A:A)
A9: 7792528011 | B9: Serums | C9: https://www.amazon.com/Best-Sellers/zgbs/beauty/7792528011 | D9: =COUNT('Serums'!A:A)
A10: de:122877031 | B10: Fragrances | C10: https://www.amazon.com/Best-Sellers/zgbs/beauty/de:122877031 | D10: =COUNT('Fragrances'!A:A)
A11: de:122878031 | B11: Skin Care | C11: https://www.amazon.com/Best-Sellers/zgbs/beauty/de:122878031 | D11: =COUNT('Skin Care'!A:A)
A12: de:122880031 | B12: Make-up | C12: https://www.amazon.com/Best-Sellers/zgbs/beauty/de:122880031 | D12: =COUNT('Make-up'!A:A)
A13: de:64272031 | B13: Bath & Body | C13: https://www.amazon.com/Best-Sellers/zgbs/beauty/de:64272031 | D13: =COUNT('Bath & Body'!A:A)
A14: de:64486031 | B14: Hair Care | C14: https://www.amazon.com/Best-Sellers/zgbs/beauty/de:64486031 | D14: =COUNT('Hair Care'!A:A)
A15: es:4347676031 | B15: Bath & Body | C15: https://www.amazon.com/Best-Sellers/zgbs/beauty/es:4347676031 | D15: =COUNT('Bath & Body'!A:A)
A16: es:4347698031 | B16: Hair Care | C16: https://www.amazon.com/Best-Sellers/zgbs/beauty/es:4347698031 | D16: =COUNT('Hair Care'!A:A)
A17: es:6397798031 | B17: Fragrances | C17: https://www.amazon.com/Best-Sellers/zgbs/beauty/es:6397798031 | D17: =COUNT('Fragrances'!A:A)
A18: es:6397823031 | B18: Make-up | C18: https://www.amazon.com/Best-Sellers/zgbs/beauty/es:6397823031 | D18: =COUNT('Make-up'!A:A)
A19: es:6397934031 | B19: Skin Care | C19: https://www.amazon.com/Best-Sellers/zgbs/beauty/es:6397934031 | D19: =COUNT('Skin Care'!A:A)
A20: fr:210965031 | B20: Fragrances | C20: https://www.amazon.com/Best-Sellers/zgbs/beauty/fr:210965031 | D20: =COUNT('Fragrances'!A:A)
A21: fr:210972031 | B21: Make up | C21: https://www.amazon.com/Best-Sellers/zgbs/beauty/fr:210972031 | D21: =COUNT('Make up'!A:A)
A22: fr:211020031 | B22: Skin Care | C22: https://www.amazon.com/Best-Sellers/zgbs/beauty/fr:211020031 | D22: =COUNT('Skin Care'!A:A)
A23: fr:211038031 | B23: Hair Care | C23: https://www.amazon.com/Best-Sellers/zgbs/beauty/fr:211038031 | D23: =COUNT('Hair Care'!A:A)
A24: fr:212073031 | B24: Bath & Body | C24: https://www.amazon.com/Best-Sellers/zgbs/beauty/fr:212073031 | D24: =COUNT('Bath & Body'!A:A)
A25: uk:118423031 | B25: Make-up | C25: https://www.amazon.com/Best-Sellers/zgbs/beauty/uk:118423031 | D25: =COUNT('Make-up'!A:A)
A26: uk:118457031 | B26: Fragrances | C26: https://www.amazon.com/Best-Sellers/zgbs/beauty/uk:118457031 | D26: =COUNT('Fragrances'!A:A)
A27: uk:118464031 | B27: Skin Care | C27: https://www.amazon.com/Best-Sellers/zgbs/beauty/uk:118464031 | D27: =COUNT('Skin Care'!A:A)
A28: uk:66469031 | B28: Hair Care | C28: https://www.amazon.com/Best-Sellers/zgbs/beauty/uk:66469031 | D28: =COUNT('Hair Care'!A:A)
A29: uk:74129031 | B29: Bath & Body | C29: https://www.amazon.com/Best-Sellers/zgbs/beauty/uk:74129031 | D29: =COUNT('Bath & Body'!A:A)

Sheet Body Washes
A1: Amazon Best Sellers — Body Washes | I1: 🔗 Best Sellers 페이지 열기
A2: rank | B2: asin | C2: title | D2: rating | E2: ratings_count | F2: price | G2: currency | H2: offers_text | I2: url
A3: 1 | B3: B0DPHQRLJC | C3: eos Cashmere Body Wash- Vanilla Cashmere, Creamy Gel with Shea Butter, 16 fl oz | D3: 4.7 | E3: 23034 | F3: 9.98 | G3: USD | I3: https://www.amazon.com/eos-Moisturizing-Nourishing-Phthalate-Sensitive/dp/B0DPHQRLJC/ref=zg_bs_g_11056291_d_sccl_1/136-1893143-0116527
A4: 2 | B4: B00MEDOY2G | C4: Dove Body Wash Body Wash Deep Moisture 30.6 oz Pump, Sulfate Free | Dove Deep Moisture Body Wash hydrates dry skin for 24 hou | D4: 4.8 | E4: 86156 | F4: 10.99 | G4: USD | I4: https://www.amazon.com/Dove-24hr-Lotion-Body-Moisture/dp/B00MEDOY2G/ref=zg_bs_g_11056291_d_sccl_2/136-1893143-0116527
A5: 3 | B5: B0B1PDDLGZ | C5: Naturium The Glow Getter Multi-Oil Body Wash, 16.9 fl oz | Nourishing Gentle Cleanser, Dissolves Impurities, Hydrating Base P | D5: 4.6 | E5: 7549 | F5: 15.18 | G5: USD | I5: https://www.amazon.com/Getter-Multi-Oil-Hydrating-Naturium-Cleanser/dp/B0B1PDDLGZ/ref=zg_bs_g_11056291_d_sccl_3/136-1893143-0116527
A6: 4 | B6: B0BT1WL6KY | C6: method Body Wash, Simply Nourish, 28 fl oz | Soothing Formula, Leaves Skin Feeling Soft & Moisturized, Made Without Parabens, | D6: 4.7 | E6: 13383 | F6: 12 | G6: USD | I6: https://www.amazon.com/Method-Simply-Nourish-Paraben-Phthalate/dp/B0BT1WL6KY/ref=zg_bs_g_11056291_d_sccl_4/136-1893143-0116527
A7: 5 | B7: B09DDD6YGJ | C7: Dove Body Wash Antibacterial For All Skin Types 30.6 oz Pump, Sulfate Free | Dove Antibacterial Body Wash eliminates 99% of b | D7: 4.8 | E7: 6609 | F7: 10.97 | G7: USD | I7: https://www.amazon.com/Dove-Body-Wash-Care-Protect/dp/B09DDD6YGJ/ref=zg_bs_g_11056291_d_sccl_5/136-1893143-0116527
A8: 6 | B8: B00SK71SAG | C8: Dove Sensitive Skin Body Wash, 24hr Lotion-Soft Skin, 30.6 oz | Dove Sensitive Skin Body Wash soothes dry, sensitive skin wit | D8: 4.8 | E8: 63650 | F8: 10.97 | G8: USD | I8: https://www.amazon.com/Dove-24hr-Lotion-Body-Sensitive/dp/B00SK71SAG/ref=zg_bs_g_11056291_d_sccl_6/136-1893143-0116527
A9: 7 | B9: B09M7SPFSJ | C9: Ivory Body Wash, Designed for the Whole Family, Gentle Formula, Free of Dyes Heavy Perfumes Parabens Phthalates & Silicones, | D9: 4.8 | E9: 20424 | F9: 6.97 | G9: USD | I9: https://www.amazon.com/Designed-Perfumes-Parabens-Phthalates-Silicones/dp/B09M7SPFSJ/ref=zg_bs_g_11056291_d_sccl_7/136-1893143-0116527
A10: 8 | B10: B0B9CHS3LR | C10: Native Clean Body Wash, Gentle & pH-balanced for Sensitive Skin, 24-Hr Freshness for Women & Men, Vegan & Cruelty-Free, Free | D10: 4.6 | E10: 2244 | F10: 15.97 | G10: USD | I10: https://www.amazon.com/Native-pH-balanced-Sensitive-Cruelty-Free-Phthalates/dp/B0B9CHS3LR/ref=zg_bs_g_11056291_d_sccl_8/136-1893143-0116527
A11: 9 | B11: B0FY7963T5 | C11: Native Clean Body Wash, Gentle & pH-balanced for Sensitive Skin, 24-Hr Freshness for Men & Women, Vegan & Cruelty-Free, Free | D11: 4.6 | E11: 7025 | F11: 9.87 | G11: USD | I11: https://www.amazon.com/Native-pH-balanced-Sensitive-Cruelty-Free-Phthalates/dp/B0FY7963T5/ref=zg_bs_g_11056291_d_sccl_9/136-1893143-0116527
A12: 10 | B12: B0BT1WN3ZD | C12: method Men’s Body Wash, Sea + Surf Scent, 28 fl oz | Soothing Formula, Leaves Skin Feeling Soft & Moisturized, Rich Lather, M | D12: 4.7 | E12: 7132 | F12: 12 | G12: USD | I12: https://www.amazon.com/method-mens-Body-Wash-Surf/dp/B0BT1WN3ZD/ref=zg_bs_g_11056291_d_sccl_10/136-1893143-0116527
A13: 11 | B13: B09GN1YRVP | C13: Irish Spring Body Wash for Men, Original Scent, 887 mL | Face and Body Wash, Men’s Body Wash, Paraben-Free, Moisturizing, Ret | D13: 4.7 | E13: 27798 | F13: 6.94 | G13: USD | I13: https://www.amazon.com/Irish-Spring-Original-Clean-Body/dp/B09GN1YRVP/ref=zg_bs_g_11056291_d_sccl_11/136-1893143-0116527
A14: 12 | B14: B09G2S1KZ2 | C14: Salt & Stone Body Wash for Women & Men, Bergamot & Hinoki 15.2 fl oz | Shower Gel, Sulfate-Free, Paraben-Free, Dye-Free, Vega | D14: 4.3 | E14: 9092 | F14: 36 | G14: USD | I14: https://www.amazon.com/Salt-Stone-Antioxidant-Rich-Body-Wash/dp/B09G2S1KZ2/ref=zg_bs_g_11056291_d_sccl_12/136-1893143-0116527
... A32: 30 | B32: B0B3FVL358 | C32: Aveeno Kids Face & Body Wash, Sensitive Skin, 18 fl. oz | Nourishing Oat Extract Washes Away Dirt and Germs Without Drying, T | D32: 4.8 | E32: 5637 | F32: 10.98 | G32: USD | I32: https://www.amazon.com/Aveeno-Sensitive-Tear-Free-Suitable-Hypoallergenic/dp/B0B3FVL358/ref=zg_bs_g_11056291_d_sccl_30/136-1893143-0116527
A33: 31 | B33: B0CGYP4GYY
A34: 32 | B34: B0DGVP5ZPK
A35: 33 | B35: B0DB6BQ798
A36: 34 | B36: B07ND4W7WR
A37: 35 | B37: B0G4X32SPX
A38: 36 | B38: B07HHHMJ6V
A39: 37 | B39: B0FX5PDSZ2
A40: 38 | B40: B0G3XRG17W
A41: 39 | B41: B07FD24RTR
A42: 40 | B42: B08BJVHYSC
A43: 41 | B43: B0CNFGXBFY
A44: 42 | B44: B0FBGWN3YH
... A52: 50 | B52: B00ZY65OSI
A53: 51 | B53: B09DDD1VS7 | C53: Dove Body Wash Body Wash Gentle Exfoliate Sea Minerals 30.6 oz Sulfate Free | Dove Gentle Exfoliating Body Wash buffs away du | D53: 4.7 | E53: 2345 | F53: 10.97 | G53: USD | I53: https://www.amazon.com/Dove-Exfoliate-Minerals-Lotion-Soft-Moisturizing/dp/B09DDD1VS7/ref=zg_bs_g_11056291_d_sccl_1/136-1893143-0116527
A54: 52 | B54: B0G4B3XLT9 | C54: Olay Body Wash for Women, Fresh Radiance, 24/7 Skin-Loving Freshness, Visibly Radiant, Plant Based Cleansers, Vitamin B3 & An | D54: 4.8 | E54: 1426 | F54: 9.09 | G54: USD | I54: https://www.amazon.com/Olay-Skin-Loving-Freshness-Antioxidant-Strawberry/dp/B0G4B3XLT9/ref=zg_bs_g_11056291_d_sccl_2/136-1893143-0116527
A55: 53 | B55: B00OQ1ZKO0 | C55: NIVEA MEN Maximum Hydration 3-in-1 Body Wash, Multipack, 3 x 16.9 FL OZ | 3-in-1 Moisturizing Body Wash, Hair and Face Wash f | D55: 4.6 | E55: 31187 | F55: 13.11 | G55: USD | I55: https://www.amazon.com/NIVEA-Men-Maximum-Hydration-Body/dp/B00OQ1ZKO0/ref=zg_bs_g_11056291_d_sccl_3/136-1893143-0116527
A56: 54 | B56: B0BVNG2MB1 | C56: Saltair Body Wash 2-Pack | Santal Bloom Moisturizing Shower Gel | 2x 17oz | Gentle easy-rinsing lather for a comfortable stra | D56: 4.3 | E56: 3346 | F56: 28 | G56: USD | I56: https://www.amazon.com/Saltair-2-Pack-Moisturizing-Cleanser-Cruelty-Free/dp/B0BVNG2MB1/ref=zg_bs_g_11056291_d_sccl_4/136-1893143-0116527
A57: 55 | B57: B0DYKBCL5G | C57: Duke Cannon Supply Co. Thick High Viscosity Body Wash - 3X Thicker, Cleansing Shower and Bath Gel, Mineral-Enriched Body Wash | D57: 4.5 | E57: 1498 | F57: 7.98 | G57: USD | I57: https://www.amazon.com/Duke-Cannon-Supply-Co-Viscosity/dp/B0DYKBCL5G/ref=zg_bs_g_11056291_d_sccl_5/136-1893143-0116527
A58: 56 | B58: B0DNGVCCZ2 | C58: The Body Wash Eucalyptus. Multi-Oil Niacinamide Shower Gel Sensitive Skin | For Women & Men. Non-Comedogenic, Hypoallergenic | D58: 4.5 | E58: 2387 | F58: 42 | G58: USD | I58: https://www.amazon.com/Fragrance-Free-Multi-Oil-Niacinamide-Shower/dp/B0DNGVCCZ2/ref=zg_bs_g_11056291_d_sccl_6/136-1893143-0116527
A59: 57 | B59: B0DT529BQK | C59: Harry's Men's Body Wash - Stone - 18 fl oz (3 Pack) | Shower Gel for Men - No Parabens, Sulfates, or Dyes | D59: 4.6 | E59: 2903 | F59: 23.91 | G59: USD | I59: https://www.amazon.com/Harrys-Mens-Body-Wash-Parabens/dp/B0DT529BQK/ref=zg_bs_g_11056291_d_sccl_7/136-1893143-0116527
A60: 58 | B60: B001G60EK8 | C60: L'OCCITANE Almond Shower Oil, Cleansing Body Wash & Shaving Base, Vegan | Purifies & smooths, non-drying, milky lather, gentl | D60: 4.4 | E60: 17668 | F60: 29 | G60: USD | I60: https://www.amazon.com/LOccitane-Cleansing-Softening-Almond-Shower/dp/B001G60EK8/ref=zg_bs_g_11056291_d_sccl_8/136-1893143-0116527
A61: 59 | B61: B0CNKZW8HL | C61: Dove Men Moisturizing Body Wash, Sandalwood + Cardamom Oil, 26oz | For dry skin, Helps nourish and refresh, With plant-based | D61: 4.6 | E61: 6518 | F61: 10.97 | G61: USD | I61: https://www.amazon.com/DOVE-MEN-Moisturizing-Dermatologist-Sandalwood/dp/B0CNKZW8HL/ref=zg_bs_g_11056291_d_sccl_9/136-1893143-0116527
A62: 60 | B62: B0FC8SRSM4 | C62: Old Spice Body Wash for Men, Fallidudes Edition, 24/7 Frightful Freshness, Long Lasting Cleanse & Refresh, Rich Lather, PumpK | D62: 4.6 | E62: 2829 | F62: 7.99 | G62: USD | I62: https://www.amazon.com/Old-Spice-Holidudes-Freshness-Stocking/dp/B0FC8SRSM4/ref=zg_bs_g_11056291_d_sccl_10/136-1893143-0116527
A63: 61 | B63: B0CGZ4FWZG | C63: Dove Serum + Acne Clear Body Wash with 1% Salicylic Acid, 18.5 oz | For acne-prone skin, Helps clear and prevent acne, With 1 | D63: 4.6 | E63: 2470 | F63: 9.97 | G63: USD | I63: https://www.amazon.com/Dove-prevent-clearing-salicylic-treatment/dp/B0CGZ4FWZG/ref=zg_bs_g_11056291_d_sccl_11/136-1893143-0116527
A64: 62 | B64: B0CNBTJ6NY | C64: Dove Ultra Sensitive Serum Body Wash Fragrance Free 10 Ingredients, 18.5 oz | For sensitive skin, Helps moisturize skin, Frag | D64: 4.6 | E64: 2397 | F64: 9.97 | G64: USD | I64: https://www.amazon.com/Dove-Fragrance-Sensitive-essential-ingredients/dp/B0CNBTJ6NY/ref=zg_bs_g_11056291_d_sccl_12/136-1893143-0116527
...

Sheet Skin Care
A1: Amazon Best Sellers — Skin Care | I1: 🔗 Best Sellers 페이지 열기
A2: rank | B2: asin | C2: title | D2: rating | E2: ratings_count | F2: price | G2: currency | H2: offers_text | I2: url
A3: 1 | B3: B09V7Z4TJG | C3: medicube Toner Pads Zero Pore Pad 2.0 for Exfoliation and Pore Care | Dual-Textured Facial Pad with 4.5% AHA Lactic Acid, 0.4 | D3: 4.6 | E3: 30722 | F3: 15.12 | G3: USD | I3: https://www.amazon.com/Medicube-Zero-Pore-Pads-Dual-Textured/dp/B09V7Z4TJG/ref=zg_bs_g_11060451_d_sccl_1/136-1893143-0116527
A4: 2 | B4: B08KT2Z93D | C4: eos Shea Better Body Lotion- Vanilla Cashmere, 24-Hour Moisture, 16 fl oz | D4: 4.7 | E4: 74360 | F4: 9.97 | G4: USD | I4: https://www.amazon.com/eos-Cashmere-Moisture-Lightweight-Non-Greasy/dp/B08KT2Z93D/ref=zg_bs_g_11060451_d_sccl_2/136-1893143-0116527
A5: 3 | B5: B07PBXXNCY | C5: Clean Skin Club Clean Towels XL®, 100% USDA Biobased Face Towel, Disposable Face Towelette, Eczema Association Accepted, Make | D5: 4.7 | E5: 51792 | F5: 17.95 | G5: USD | I5: https://www.amazon.com/Clean-Skin-Club-Disposable-Sensitive/dp/B07PBXXNCY/ref=zg_bs_g_11060451_d_sccl_3/136-1893143-0116527
A6: 4 | B6: B00F1U0YB4 | C6: Mrs. Meyer's Clean Day, Hand Soap Refill, Lemon Verbena Scent, 33 Fl Oz | D6: 4.7 | E6: 120923 | F6: 4.98 | G6: USD | I6: https://www.amazon.com/Mrs-Meyers-Clean-Refill-Verbena/dp/B00F1U0YB4/ref=zg_bs_g_11060451_d_sccl_4/136-1893143-0116527
A7: 5 | B7: B074PVTPBW | C7: Mighty Patch Hero Cosmetics Original Nighttime Acne Pimple Patches, 36 Ct | #1 Hydrocolloid Acne Patches, Shrinking Zits & Wh | D7: 4.6 | E7: 184770 | F7: 12.99 | G7: USD | I7: https://www.amazon.com/Mighty-Patch-Hydrocolloid-Absorbing-count/dp/B074PVTPBW/ref=zg_bs_g_11060451_d_sccl_5/136-1893143-0116527
A8: 6 | B8: B00U2VQZDS | C8: Neutrogena Makeup Remover Micellar Wipes, 2 Pack of 25 Ct | Plant-Based Micellar Water Cleansing Cloths, Gently Removes Oil, | D8: 4.8 | E8: 121294 | F8: 9.97 | G8: USD | I8: https://www.amazon.com/Neutrogena-Makeup-Remover-Micellar-Wipes/dp/B00U2VQZDS/ref=zg_bs_g_11060451_d_sccl_6/136-1893143-0116527
A9: 7 | B9: B071914GGL | C9: The Ordinary Glycolic Acid 7% Exfoliating Toner, Brightening and Smoothing Daily Toner for More Even-Looking Skin Tone | D9: 4.7 | E9: 61699 | F9: 13.5 | G9: USD | I9: https://www.amazon.com/Ordinary-Exfoliating-Brightening-Smoothing-Even-Looking/dp/B071914GGL/ref=zg_bs_g_11060451_d_sccl_7/136-1893143-0116527
A10: 8 | B10: B081KL2QYJ | C10: PanOxyl 10% Benzoyl Peroxide Acne Foaming Wash, Maximum Strength, Daily Acne-Fighting Face and Body Cleanser, Face Wash to Cl | D10: 4.6 | E10: 82880 | F10: 10.19 | G10: USD | I10: https://www.amazon.com/PanOxyl-Foaming-Peroxide-Strength-Antimicrobial/dp/B081KL2QYJ/ref=zg_bs_g_11060451_d_sccl_8/136-1893143-0116527
A11: 9 | B11: B0B2RM68G2 | C11: BIODANCE Bio-Collagen Real Deep Mask, Hydrating Overnight Hydrogel Face Mask, Pore Minimizing, Elasticity, Plumping, Travel E | D11: 4.5 | E11: 46170 | F11: 19 | G11: USD | I11: https://www.amazon.com/Biodance-Bio-Collagen-Tightening-Hydrating-Molecular/dp/B0B2RM68G2/ref=zg_bs_g_11060451_d_sccl_9/136-1893143-0116527
A12: 10 | B12: B0DPHQRLJC | C12: eos Cashmere Body Wash- Vanilla Cashmere, Creamy Gel with Shea Butter, 16 fl oz | D12: 4.7 | E12: 23034 | F12: 9.98 | G12: USD | I12: https://www.amazon.com/eos-Moisturizing-Nourishing-Phthalate-Sensitive/dp/B0DPHQRLJC/ref=zg_bs_g_11060451_d_sccl_10/136-1893143-0116527
A13: 11 | B13: B0DGPSZVW3 | C13: medicube Jelly Cream with Collagen & Niacinamide, 1.69 fl.oz | Freeze-Dried Hydrolyzed Collagen for Skin Barrier Hydration, 2 | D13: 4.5 | E13: 35843 | F13: 9.9 | G13: USD | I13: https://www.amazon.com/medicube-Collagen-Niacinamide-Freeze-Dried-Hydrolyzed/dp/B0DGPSZVW3/ref=zg_bs_g_11060451_d_sccl_11/136-1893143-0116527
A14: 12 | B14: B09HHDHXWX | C14: Amazon Basics Gentle & Mild Clear Liquid Hand Soap Refill, Triclosan-Free, Dermatologist-Tested, pH Balanced, Cruelty-Free, 5 | D14: 4.6 | E14: 45731 | F14: 5.15 | G14: USD | I14: https://www.amazon.com/Amazon-Basics-Gentle-Liquid-Triclosan-free/dp/B09HHDHXWX/ref=zg_bs_g_11060451_d_sccl_12/136-1893143-0116527
... A32: 30 | B32: B0D2Z3GGCY | C32: medicube Capsule Cream with Deep Vitamin C for Radiance | Liposome Vitamin C Golden Capsule for Radiance & Firm-Looking Skin | D32: 4.6 | E32: 26361 | F32: 16.9 | G32: USD | I32: https://www.amazon.com/medicube-Liposome-Radiance-Firm-Looking-Hydrating/dp/B0D2Z3GGCY/ref=zg_bs_g_11060451_d_sccl_30/136-1893143-0116527
A33: 31 | B33: B0B1PDDLGZ
A34: 32 | B34: B00365DABC
A35: 33 | B35: B0BRMYHMS5
A36: 34 | B36: B00949CTQQ
A37: 35 | B37: B0CZF2T7CK
A38: 36 | B38: B0BT1WL6KY
A39: 37 | B39: B0DWFLY18Y
A40: 38 | B40: B0GD6R7CFJ
A41: 39 | B41: B081FFRGZB
A42: 40 | B42: B0FKGJYFC8
A43: 41 | B43: B09DDD6YGJ
A44: 42 | B44: B06WD5J8KY
... A52: 50 | B52: B0BX2TZZWG
A53: 51 | B53: B0GVQ6NYR3 | C53: medicube PDRN Collagen Gua Sha Neck Wrinkle Cream - Firming, Contour Care | Built-In Gua Sha Massager with Volufiline 5% - Fo | D53: 4.4 | E53: 509 | F53: 22.9 | G53: USD | I53: https://www.amazon.com/medicube-PDRN-Collagen-Wrinkle-Cream/dp/B0GVQ6NYR3/ref=zg_bs_g_11060451_d_sccl_1/136-1893143-0116527
A54: 52 | B54: B09M7SPFSJ | C54: Ivory Body Wash, Designed for the Whole Family, Gentle Formula, Free of Dyes Heavy Perfumes Parabens Phthalates & Silicones, | D54: 4.8 | E54: 20424 | F54: 6.97 | G54: USD | I54: https://www.amazon.com/Designed-Perfumes-Parabens-Phthalates-Silicones/dp/B09M7SPFSJ/ref=zg_bs_g_11060451_d_sccl_2/136-1893143-0116527
A55: 53 | B55: B0060OUV5Y | C55: La Roche-Posay Cicaplast Balm B5, Barrier Repair Cream for Dry Skin | Skin healing cream with centella asiatica, shea butter | D55: 4.7 | E55: 22617 | F55: 18.99 | G55: USD | I55: https://www.amazon.com/Roche-Posay-Cicaplast-Baume-Multi-Purpose-Butter/dp/B0060OUV5Y/ref=zg_bs_g_11060451_d_sccl_3/136-1893143-0116527
A56: 54 | B56: B0B9CHS3LR | C56: Native Clean Body Wash, Gentle & pH-balanced for Sensitive Skin, 24-Hr Freshness for Women & Men, Vegan & Cruelty-Free, Free | D56: 4.6 | E56: 2244 | F56: 15.97 | G56: USD | I56: https://www.amazon.com/Native-pH-balanced-Sensitive-Cruelty-Free-Phthalates/dp/B0B9CHS3LR/ref=zg_bs_g_11060451_d_sccl_4/136-1893143-0116527
A57: 55 | B57: B0G38FGSKL | C57: medicube Eye Patch PDRN Caffeine Collagen - Firming Gel Patches, | Age-Defying Care with Retinol & Collagen - Gel Patches for | D57: 4.4 | E57: 982 | F57: 16.9 | G57: USD | I57: https://www.amazon.com/medicube-Caffeine-Collagen-appearance-Age-Defying/dp/B0G38FGSKL/ref=zg_bs_g_11060451_d_sccl_5/136-1893143-0116527
A58: 56 | B58: B0BWX6NZLT | C58: NOONI Korean Lip Oil - Applepeony - pH Color-Changing Plumping Lip Gloss | 24HR Hydration, Moisturizing Lip Oil, Natural Lip | D58: 4 | E58: 25865 | F58: 9.99 | G58: USD | I58: https://www.amazon.com/NOONI-Korean-Lip-Oil-Moisturizing/dp/B0BWX6NZLT/ref=zg_bs_g_11060451_d_sccl_6/136-1893143-0116527
A59: 57 | B59: B00SNPCSUY | C59: CeraVe Night Cream, Face Moisturizer, Skin Care for Dry Skin, 1.7oz | Skin Renewing Face Moisturizer with Hyaluronic Acid & P | D59: 4.6 | E59: 56956 | F59: 15.44 | G59: USD | I59: https://www.amazon.com/CeraVe-Skin-Renewing-Night-Cream/dp/B00SNPCSUY/ref=zg_bs_g_11060451_d_sccl_7/136-1893143-0116527
A60: 58 | B60: B084ZP848Y | C60: Blue Lizard Sensitive Mineral SPF 50 Sunscreen Lotion, 100% Mineral Sunscreen, UVA/UVB Protection, Infused with organic Aloe | D60: 4.4 | E60: 21370 | F60: 15.48 | G60: USD | I60: https://www.amazon.com/Blue-Lizard-Sensitive-Mineral-Sunscreen/dp/B084ZP848Y/ref=zg_bs_g_11060451_d_sccl_8/136-1893143-0116527
A61: 59 | B61: B0054LHI5A | C61: Burt's Bees 100% Natural Moisturizing Lip Balm (Original Beeswax) | D61: 4.8 | E61: 121440 | F61: 10.48 | G61: USD | I61: https://www.amazon.com/Burts-Bees-Moisturizing-Original-Peppermint/dp/B0054LHI5A/ref=zg_bs_g_11060451_d_sccl_9/136-1893143-0116527
A62: 60 | B62: B0FY7963T5 | C62: Native Clean Body Wash, Gentle & pH-balanced for Sensitive Skin, 24-Hr Freshness for Men & Women, Vegan & Cruelty-Free, Free | D62: 4.6 | E62: 7025 | F62: 9.87 | G62: USD | I62: https://www.amazon.com/Native-pH-balanced-Sensitive-Cruelty-Free-Phthalates/dp/B0FY7963T5/ref=zg_bs_g_11060451_d_sccl_10/136-1893143-0116527
A63: 61 | B63: B006IB5T4W | C63: Aquaphor Advanced Therapy Healing Ointment Skin Protectant, 14 OZ | Clinically Proven Skin Protectant Moisturizer for Cracked | D63: 4.8 | E63: 86898 | F63: 16.49 | G63: USD | I63: https://www.amazon.com/Aquaphor-Healing-Ointment-Moisturizing-Protectant/dp/B006IB5T4W/ref=zg_bs_g_11060451_d_sccl_11/136-1893143-0116527
A64: 62 | B64: B00I69SEK0 | C64: Dove Beauty Bar Soap Original 8 Count for Soft, Smooth Skin, with 1/4 Moisturizing Cream 3.75 oz | D64: 4.8 | E64: 12327 | F64: 12.97 | G64: USD | I64: https://www.amazon.com/Dove-Beauty-Bar-White/dp/B00I69SEK0/ref=zg_bs_g_11060451_d_sccl_12/136-1893143-0116527
...

Sheet Body
A1: Amazon Best Sellers — Body | I1: 🔗 Best Sellers 페이지 열기
A2: rank | B2: asin | C2: title | D2: rating | E2: ratings_count | F2: price | G2: currency | H2: offers_text | I2: url
A3: 1 | B3: B08KT2Z93D | C3: eos Shea Better Body Lotion- Vanilla Cashmere, 24-Hour Moisture, 16 fl oz | D3: 4.7 | E3: 74360 | F3: 9.97 | G3: USD | I3: https://www.amazon.com/eos-Cashmere-Moisture-Lightweight-Non-Greasy/dp/B08KT2Z93D/ref=zg_bs_g_11060521_d_sccl_1/136-1893143-0116527
A4: 2 | B4: B00F1U0YB4 | C4: Mrs. Meyer's Clean Day, Hand Soap Refill, Lemon Verbena Scent, 33 Fl Oz | D4: 4.7 | E4: 120923 | F4: 7.61 | G4: USD | I4: https://www.amazon.com/Mrs-Meyers-Clean-Refill-Verbena/dp/B00F1U0YB4/ref=zg_bs_g_11060521_d_sccl_2/136-1893143-0116527
A5: 3 | B5: B0DPHQRLJC | C5: eos Cashmere Body Wash- Vanilla Cashmere, Creamy Gel with Shea Butter, 16 fl oz | D5: 4.7 | E5: 23034 | F5: 9.98 | G5: USD | I5: https://www.amazon.com/eos-Moisturizing-Nourishing-Phthalate-Sensitive/dp/B0DPHQRLJC/ref=zg_bs_g_11060521_d_sccl_3/136-1893143-0116527
A6: 4 | B6: B09HHDHXWX | C6: Amazon Basics Gentle & Mild Clear Liquid Hand Soap Refill, Triclosan-Free, Dermatologist-Tested, pH Balanced, Cruelty-Free, 5 | D6: 4.6 | E6: 45731 | F6: 5.15 | G6: USD | I6: https://www.amazon.com/Amazon-Basics-Gentle-Liquid-Triclosan-free/dp/B09HHDHXWX/ref=zg_bs_g_11060521_d_sccl_4/136-1893143-0116527
A7: 5 | B7: B00MEDOY2G | C7: Dove Body Wash Body Wash Deep Moisture 30.6 oz Pump, Sulfate Free | Dove Deep Moisture Body Wash hydrates dry skin for 24 hou | D7: 4.8 | E7: 86156 | F7: 10.99 | G7: USD | I7: https://www.amazon.com/Dove-24hr-Lotion-Body-Moisture/dp/B00MEDOY2G/ref=zg_bs_g_11060521_d_sccl_5/136-1893143-0116527
A8: 6 | B8: B07RK4HST7 | C8: CeraVe Daily Moisturizing Lotion, Face and Body Lotion, Skin care, 19oz | Hyaluronic Acid, Lotion For Dry Skin, Skin Barrier | D8: 4.7 | E8: 150328 | F8: 18.14 | G8: USD | I8: https://www.amazon.com/CeraVe-Moisturizing-Lotion-Hyaluronic-Fragrance/dp/B07RK4HST7/ref=zg_bs_g_11060521_d_sccl_6/136-1893143-0116527
A9: 7 | B9: B0B1PDDLGZ | C9: Naturium The Glow Getter Multi-Oil Body Wash, 16.9 fl oz | Nourishing Gentle Cleanser, Dissolves Impurities, Hydrating Base P | D9: 4.6 | E9: 7549 | F9: 15.18 | G9: USD | I9: https://www.amazon.com/Getter-Multi-Oil-Hydrating-Naturium-Cleanser/dp/B0B1PDDLGZ/ref=zg_bs_g_11060521_d_sccl_7/136-1893143-0116527
A10: 8 | B10: B0BT1WL6KY | C10: method Body Wash, Simply Nourish, 28 fl oz | Soothing Formula, Leaves Skin Feeling Soft & Moisturized, Made Without Parabens, | D10: 4.7 | E10: 13383 | F10: 12 | G10: USD | I10: https://www.amazon.com/Method-Simply-Nourish-Paraben-Phthalate/dp/B0BT1WL6KY/ref=zg_bs_g_11060521_d_sccl_8/136-1893143-0116527
A11: 9 | B11: B081FFRGZB | C11: Softsoap Antibacterial Liquid Hand Soap, White Tea & Berry Scent, 50 fl oz | Refill Size, Paraben-Free, Phthalate-Free, Bathr | D11: 4.6 | E11: 22355 | F11: 5.97 | G11: USD | I11: https://www.amazon.com/Softsoap-Antibacterial-Liquid-Refill-White/dp/B081FFRGZB/ref=zg_bs_g_11060521_d_sccl_9/136-1893143-0116527
A12: 10 | B12: B09DDD6YGJ | C12: Dove Body Wash Antibacterial For All Skin Types 30.6 oz Pump, Sulfate Free | Dove Antibacterial Body Wash eliminates 99% of b | D12: 4.8 | E12: 6609 | F12: 10.97 | G12: USD | I12: https://www.amazon.com/Dove-Body-Wash-Care-Protect/dp/B09DDD6YGJ/ref=zg_bs_g_11060521_d_sccl_10/136-1893143-0116527
A13: 11 | B13: B00SK71SAG | C13: Dove Sensitive Skin Body Wash, 24hr Lotion-Soft Skin, 30.6 oz | Dove Sensitive Skin Body Wash soothes dry, sensitive skin wit | D13: 4.8 | E13: 63650 | F13: 10.97 | G13: USD | I13: https://www.amazon.com/Dove-24hr-Lotion-Body-Sensitive/dp/B00SK71SAG/ref=zg_bs_g_11060521_d_sccl_11/136-1893143-0116527
A14: 12 | B14: B001ET7IQK | C14: Dove Beauty Bar Soap Sensitive, 8 Bars for Sensitive Skin, Fragrance Free and Hypoallergenic 3.75 oz | D14: 4.8 | E14: 18305 | F14: 12.97 | G14: USD | I14: https://www.amazon.com/Dove-Beauty-Sensitive-Skin-Count/dp/B001ET7IQK/ref=zg_bs_g_11060521_d_sccl_12/136-1893143-0116527
... A32: 30 | B32: B001459IEE | C32: Aveeno Daily Moisturizing Body Lotion for Normal to Dry Skin, Moisturizer with Soothing Prebiotic Oat, Non Greasy, Non Comedo | D32: 4.8 | E32: 58966 | F32: 9.97 | G32: USD | I32: https://www.amazon.com/Aveeno-Moisturizing-Soothing-Emollients-Fragrance-Free/dp/B001459IEE/ref=zg_bs_g_11060521_d_sccl_30/136-1893143-0116527
A33: 31 | B33: B00028EYJ8
A34: 32 | B34: B07ZDHQQW1
A35: 33 | B35: B084MVWG1F
A36: 34 | B36: B0CPCYP629
A37: 35 | B37: B0FPQ3Z16S
A38: 36 | B38: B09YZ16XCN
A39: 37 | B39: B007VC9DKI
A40: 38 | B40: B003BMJGKE
A41: 39 | B41: B0C5JWKLZG
A42: 40 | B42: B0034F9K36
A43: 41 | B43: B0F1QHNFJP
A44: 42 | B44: B079FV6PRH
... A52: 50 | B52: B0DNTZTS1L
A53: 51 | B53: B08KT2Y49F | C53: eos 24H Moisture Shea Better Body Lotion- Pomegranate Raspberry, 16 fl oz | D53: 4.7 | E53: 8855 | F53: 9.97 | G53: USD | I53: https://www.amazon.com/eos-Pomegranate-Raspberry-Lightweight-Non-Greasy/dp/B08KT2Y49F/ref=zg_bs_g_11060521_d_sccl_1/136-1893143-0116527
A54: 52 | B54: B075X2KL5C | C54: Aveeno Skin Relief Body Wash with Triple Oat Complex, Fragrance-Free, Gentle Daily Body Wash for Sensitive Skin Leaves Itchy, | D54: 4.6 | E54: 40828 | F54: 12.97 | G54: USD | I54: https://www.amazon.com/Aveeno-Fragrance-Free-Soap-Free-Dye-Free-Sensitive/dp/B075X2KL5C/ref=zg_bs_g_11060521_d_sccl_2/136-1893143-0116527
A55: 53 | B55: B08TKNMW1Z | C55: Dove Men Body & Face Wash Clean Comfort Men's Body Wash with 30 oz | For dry skin, Helps hydrate and smooth skin, With Micro | D55: 4.8 | E55: 3221 | F55: 10.97 | G55: USD | I55: https://www.amazon.com/DOVE-MEN-CARE-Clean-Comfort/dp/B08TKNMW1Z/ref=zg_bs_g_11060521_d_sccl_3/136-1893143-0116527
A56: 54 | B56: B0FNWJFQFM | C56: medicube Kojic Acid Turmeric Brightening Body Wash, 13.52 fl.oz | Shower Gel for Uneven Skin - Niacinamide, Vitamin C, AHA BH | D56: 4.6 | E56: 1367 | F56: 15.12 | G56: USD | I56: https://www.amazon.com/medicube-Brightening-Niacinamide-Cleansing-Hydrating/dp/B0FNWJFQFM/ref=zg_bs_g_11060521_d_sccl_4/136-1893143-0116527
A57: 55 | B57: B0G3XN8152 | C57: Olay Body Wash for Women, Ultra Moisture, 24/7 Moisture Barrier Repair, Hydrating Formula for Visibly Healthy Soft Skin, Vita | D57: 4.8 | E57: 9106 | F57: 10.97 | G57: USD | I57: https://www.amazon.com/Olay-Moisture-Barrier-Hydrating-Hyaluronic/dp/B0G3XN8152/ref=zg_bs_g_11060521_d_sccl_5/136-1893143-0116527
A58: 56 | B58: B0DP37D91R | C58: Mirai Clinical Persimmon Soap for Old People Smell,Nonenal® Odor Eliminator | Japanese Persimmon Soap, Natural Body Odor Soap | D58: 4.3 | E58: 2371 | F58: 17.95 | G58: USD | I58: https://www.amazon.com/MIRAI-Clinical-Persimmon-Soap-Body/dp/B0DP37D91R/ref=zg_bs_g_11060521_d_sccl_6/136-1893143-0116527
A59: 57 | B59: B0CMW64H59 | C59: Cremo Body Wash for Men, Italian Bergamot, 16 Fl Oz | Rich-lathering mens body wash, Moisturizing shower gel, Italian bergamo | D59: 4.6 | E59: 13590 | F59: 9.97 | G59: USD | I59: https://www.amazon.com/Cremo-Rich-Lathering-Italian-Bergamot-Blossom/dp/B0CMW64H59/ref=zg_bs_g_11060521_d_sccl_7/136-1893143-0116527
A60: 58 | B60: B0CK4YS1SV | C60: Dr Teal's Body Wash with Pure Epsom Salt, Relax & Relief with Eucalyptus & Spearmint, 24 fl oz (Pack of 2) | D60: 4.8 | E60: 11542 | F60: 11.74 | G60: USD | I60: https://www.amazon.com/Dr-Teals-Eucalyptus-Spearmint-Packaging/dp/B0CK4YS1SV/ref=zg_bs_g_11060521_d_sccl_8/136-1893143-0116527
A61: 59 | B61: B0BJMSH4JX | C61: Hearth & Homestead Whipped Beef Tallow for Skin & Face, Unscented, 1.3oz | 100% Grass Fed & Finished, Eczema Cream & Body But | D61: 4.6 | E61: 14479 | F61: 26.97 | G61: USD | I61: https://www.amazon.com/Hearth-Homestead-Handmade-Whipped-Unscented/dp/B0BJMSH4JX/ref=zg_bs_g_11060521_d_sccl_9/136-1893143-0116527
A62: 60 | B62: B0FKC23886 | C62: Jergens Shea Fusion Vanilla Crush Body Lotion, Dry Skin, 14 fl oz | Shea Butter and Vitamin E Moisturizing Lotion, Vanilla Sc | D62: 4.5 | E62: 5043 | F62: 6.99 | G62: USD | I62: https://www.amazon.com/Jergens-Fusion-Vanilla-Moisturizer-Vitamin/dp/B0FKC23886/ref=zg_bs_g_11060521_d_sccl_10/136-1893143-0116527
A63: 61 | B63: B002TSA90M | C63: DOVE MEN + CARE 3 in Cleanser for Body, Face, and Shaving 1 Bar 3.75 oz | For dry skin, Helps cleanse and hydrate, With 1/4 m | D63: 4.7 | E63: 14498 | F63: 12.97 | G63: USD | I63: https://www.amazon.com/Cleanser-Shaving-Facial-Moisturizing-Hydrate/dp/B002TSA90M/ref=zg_bs_g_11060521_d_sccl_11/136-1893143-0116527
A64: 62 | B64: B07MG5YJLT | C64: Mrs. Meyer's Clean Day, Hand Soap, Rain Water Scent, 12.5 Fl Oz | D64: 4.7 | E64: 23736 | F64: 4.45 | G64: USD | I64: https://www.amazon.com/Mrs-Meyers-Clean-Water-Scent/dp/B07MG5YJLT/ref=zg_bs_g_11060521_d_sccl_12/136-1893143-0116527
...

Sheet Moisturizers
A1: Amazon Best Sellers — Moisturizers | I1: 🔗 Best Sellers 페이지 열기
A2: rank | B2: asin | C2: title | D2: rating | E2: ratings_count | F2: price | G2: currency | H2: offers_text | I2: url
A3: 1 | B3: B08KT2Z93D | C3: eos Shea Better Body Lotion- Vanilla Cashmere, 24-Hour Moisture, 16 fl oz | D3: 4.7 | E3: 74360 | F3: 9.97 | G3: USD | I3: https://www.amazon.com/eos-Cashmere-Moisture-Lightweight-Non-Greasy/dp/B08KT2Z93D/ref=zg_bs_g_11060661_d_sccl_1/136-1893143-0116527
A4: 2 | B4: B07RK4HST7 | C4: CeraVe Daily Moisturizing Lotion, Face and Body Lotion, Skin care, 19oz | Hyaluronic Acid, Lotion For Dry Skin, Skin Barrier | D4: 4.7 | E4: 150328 | F4: 18.14 | G4: USD | I4: https://www.amazon.com/CeraVe-Moisturizing-Lotion-Hyaluronic-Fragrance/dp/B07RK4HST7/ref=zg_bs_g_11060661_d_sccl_2/136-1893143-0116527
A5: 3 | B5: B07BRDVQ4B | C5: AmLactin Daily Nourish Body Lotion, 12% Lactic Acid, 14.1 oz | 12% lactic acid body lotion exfoliates and moisturizes dry ski | D5: 4.4 | E5: 36976 | F5: 15.97 | G5: USD | I5: https://www.amazon.com/AmLactin-Moisturizing-Lotion-Bottle-Paraben/dp/B07BRDVQ4B/ref=zg_bs_g_11060661_d_sccl_3/136-1893143-0116527
A6: 4 | B6: B0060OUV5Y | C6: La Roche-Posay Cicaplast Balm B5, Barrier Repair Cream for Dry Skin | Skin healing cream with centella asiatica, shea butter | D6: 4.7 | E6: 22617 | F6: 18.99 | G6: USD | I6: https://www.amazon.com/Roche-Posay-Cicaplast-Baume-Multi-Purpose-Butter/dp/B0060OUV5Y/ref=zg_bs_g_11060661_d_sccl_4/136-1893143-0116527
A7: 5 | B7: B006IB5T4W | C7: Aquaphor Advanced Therapy Healing Ointment Skin Protectant, 14 OZ | Clinically Proven Skin Protectant Moisturizer for Cracked | D7: 4.8 | E7: 86898 | F7: 16.49 | G7: USD | I7: https://www.amazon.com/Aquaphor-Healing-Ointment-Moisturizing-Protectant/dp/B006IB5T4W/ref=zg_bs_g_11060661_d_sccl_5/136-1893143-0116527
A8: 6 | B8: B0D7XXQYNH | C8: Olay Body Lotion for Women, Firming with Collagen Peptides Serum, Visibly Firmer Skin, 24hr Moisture & Hydration, Fast Absorb | D8: 4.6 | E8: 15683 | F8: 9.97 | G8: USD | I8: https://www.amazon.com/Olay-Hydrating-Collagen-Moisturizing-Absorbing/dp/B0D7XXQYNH/ref=zg_bs_g_11060661_d_sccl_6/136-1893143-0116527
A9: 7 | B9: B0107QPFBU | C9: Aquaphor Advanced Therapy Healing Ointment, Skin Protectant, 7 OZ | Clinically Proven Skin Protectant Moisturizer for Cracked | D9: 4.8 | E9: 44924 | F9: 12.19 | G9: USD | I9: https://www.amazon.com/Aquaphor-Advanced-Therapy-Ointment-Protectant/dp/B0107QPFBU/ref=zg_bs_g_11060661_d_sccl_7/136-1893143-0116527
A10: 8 | B10: B099N1LC4R | C10: Cetaphil Moisturizing Cream, Face & Body Lotion Dry Sensitive Skin, 20oz | Fragrance-Free, Non-Comedogenic, Non-Greasy, Hydra | D10: 4.8 | E10: 40307 | F10: 14.12 | G10: USD | I10: https://www.amazon.com/Cetaphil-Moisturizing-Cream-Lotion-Sensitive/dp/B099N1LC4R/ref=zg_bs_g_11060661_d_sccl_8/136-1893143-0116527
A11: 9 | B11: B003QXZWYW | C11: La Roche-Posay Lipikar AP+MAX Triple Repair Moisturizing Body Cream | Face and body lotion for dry skin with shea butter and | D11: 4.6 | E11: 42015 | F11: 21.99 | G11: USD | I11: https://www.amazon.com/Roche-Posay-Lipikar-Intense-Repair-Cream/dp/B003QXZWYW/ref=zg_bs_g_11060661_d_sccl_9/136-1893143-0116527
A12: 10 | B12: B001459IEE | C12: Aveeno Daily Moisturizing Body Lotion for Normal to Dry Skin, Moisturizer with Soothing Prebiotic Oat, Non Greasy, Non Comedo | D12: 4.8 | E12: 58966 | F12: 9.97 | G12: USD | I12: https://www.amazon.com/Aveeno-Moisturizing-Soothing-Emollients-Fragrance-Free/dp/B001459IEE/ref=zg_bs_g_11060661_d_sccl_10/136-1893143-0116527
A13: 11 | B13: B0CPCYP629 | C13: eos 24H Moisture Travel Body Lotion- Vanilla Cashmere, 2.5 fl oz | D13: 4.8 | E13: 5900 | F13: 3.99 | G13: USD | I13: https://www.amazon.com/eos-Moisture-Lotion-Cashmere-Skincare/dp/B0CPCYP629/ref=zg_bs_g_11060661_d_sccl_11/136-1893143-0116527
A14: 12 | B14: B0FPQ3Z16S | C14: medicube Jelly Cream with Hyaluronic Acid for Long-lasting Hydration | Daily Moisturizer with Hyaluronic Acid, Ceramides, Mul | D14: 4.5 | E14: 35843 | F14: 9.9 | G14: USD | I14: https://www.amazon.com/medicube-Hyaluronic-Moisturizer-Long-lasting-Hydration/dp/B0FPQ3Z16S/ref=zg_bs_g_11060661_d_sccl_12/136-1893143-0116527
... A32: 30 | B32: B000RGBWPO | C32: Palmer's Solid Body Lotion, Cocoa Butter Formula with Vitamin E (7.25 Oz) | Body Moisturizer with Vitamin E for Extremely Dry | D32: 4.8 | E32: 36159 | F32: 7.16 | G32: USD | I32: https://www.amazon.com/Palmers-Formula-Therapy-Moisturizer-Extremely/dp/B000RGBWPO/ref=zg_bs_g_11060661_d_sccl_30/136-1893143-0116527
A33: 31 | B33: B004AI97MA
A34: 32 | B34: B000OYJ9AO
A35: 33 | B35: B08D43LHYP
A36: 34 | B36: B07H3YJD3R
A37: 35 | B37: B0FG8K9QYK
A38: 36 | B38: B0CWVSNVG6
A39: 37 | B39: B00BWTKA94
A40: 38 | B40: B08Q1J3V2T
A41: 39 | B41: B0CH9K3P3R
A42: 40 | B42: B0FD8W456T
A43: 41 | B43: B07SWJ5PVH
A44: 42 | B44: B00KTLXB4C
... A52: 50 | B52: B0071XPQQ2
A53: 51 | B53: B00DG8EZKO | C53: NIVEA Intense Healing Body Lotion, 72-Hour Moisturizing Lotion,16.9 FL OZ | Moisturizing Lotion with Glycerin, Provitamin B5 | D53: 4.7 | E53: 30487 | F53: 7.17 | G53: USD | I53: https://www.amazon.com/NIVEA-Intense-Healing-Body-Lotion/dp/B00DG8EZKO/ref=zg_bs_g_11060661_d_sccl_1/136-1893143-0116527
A54: 52 | B54: B000XY9LT4 | C54: Eucerin Intensive Repair Body Lotion with Urea, AHA and NMF, 16.9 FL OZ | Body Lotion for Dry, Flaky Skin, Enriched with Urea | D54: 4.7 | E54: 26765 | F54: 13.69 | G54: USD | I54: https://www.amazon.com/Eucerin-Intensive-Repair-Lotion-Bottle/dp/B000XY9LT4/ref=zg_bs_g_11060661_d_sccl_2/136-1893143-0116527
A55: 53 | B55: B0019LWU2K | C55: NOW Foods Solutions, Vegetable Glycerin, 100% Pure, Versatile Skin Care, Softening and Moisturizing, 16-Ounce | D55: 4.7 | E55: 48194 | F55: 8.56 | G55: USD | I55: https://www.amazon.com/Solutions-Vegetable-Versatile-Softening-Moisturizing/dp/B0019LWU2K/ref=zg_bs_g_11060661_d_sccl_3/136-1893143-0116527
A56: 54 | B56: B075G3RJDZ | C56: Lubriderm Daily Moisture Body Lotion, Fragrance Free, 24 fl. oz | Hydrating Face, Hand & Body Lotion + Pro-Ceramide for Sensi | D56: 4.8 | E56: 21826 | F56: 9.59 | G56: USD | I56: https://www.amazon.com/Lubriderm-Moisture-Lotion-Fragrance-Free-Normal/dp/B075G3RJDZ/ref=zg_bs_g_11060661_d_sccl_4/136-1893143-0116527
A57: 55 | B57: B09YT7WTFS | C57: Naturium Bio-Lipid Restoring Body Lotion, All Day Moisture, 14 fl oz | Nourishing Moisturizer with Shea Butter, Skin Hydratin | D57: 4.5 | E57: 3023 | F57: 14.88 | G57: USD | I57: https://www.amazon.com/Naturium-Bio-Lipid-Restoring-Moisturizing-Fragrance/dp/B09YT7WTFS/ref=zg_bs_g_11060661_d_sccl_5/136-1893143-0116527
A58: 56 | B58: B076G2XGY3 | C58: NIVEA Essentially Enriched Body Lotion, Value Pack, 2 x 16.9 FL OZ | Hydrating Body Lotion with Hyaluronic Acid, Almond Oil a | D58: 4.6 | E58: 25747 | F58: 13.47 | G58: USD | I58: https://www.amazon.com/NIVEA-Essentially-Enriched-Lotion-Fluid/dp/B076G2XGY3/ref=zg_bs_g_11060661_d_sccl_6/136-1893143-0116527
A59: 57 | B59: B01H6OYPU8 | C59: NIVEA Cocoa Butter Body Cream with Hyaluronic Acid, 16 OZ | Cocoa Butter Body Cream with Hyaluronic Acid and Deep Nourishing | D59: 4.7 | E59: 28798 | F59: 7.26 | G59: USD | I59: https://www.amazon.com/NIVEA-Hyaluronic-Nourishing-72-Hour-Moisturizer/dp/B01H6OYPU8/ref=zg_bs_g_11060661_d_sccl_7/136-1893143-0116527
A60: 58 | B60: B00DEX61A8 | C60: NIVEA MEN Maximum Hydration Lotion, 48-Hour Body Moisturizer, 16.9 FL OZ | Aloe Vera Body Lotion for Men, 3-in-1 Lotion for B | D60: 4.7 | E60: 25172 | F60: 7.26 | G60: USD | I60: https://www.amazon.com/NIVEA-MEN-Hydration-Moisture-Dermatologically-Tested/dp/B00DEX61A8/ref=zg_bs_g_11060661_d_sccl_8/136-1893143-0116527
A61: 59 | B61: B09HHBYQXY | C61: Amazon Essentials Petroleum Jelly White Petrolatum Skin Protectant, Unscented, 3.75 Ounce, 1-Pack (Previously Amazon Basics) | D61: 4.7 | E61: 8222 | F61: 4.18 | G61: USD | I61: https://www.amazon.com/Amazon-Basics-Petroleum-Petrolatum-Protectant/dp/B09HHBYQXY/ref=zg_bs_g_11060661_d_sccl_9/136-1893143-0116527
A62: 60 | B62: B013XKHA4M | C62: Sol de Janeiro Brazilian Bum Bum Cream Visibly Firming Body Cream | Iconic Cheirosa 62 Scent | D62: 4.6 | E62: 55088 | F62: 48 | G62: USD | I62: https://www.amazon.com/Sol-Janeiro-Brazilian-Bum-Cream/dp/B013XKHA4M/ref=zg_bs_g_11060661_d_sccl_10/136-1893143-0116527
A63: 61 | B63: B0009F3O8Q | C63: Palmer's Cocoa Butter Body Lotion Formula, Daily Skin Therapy (13.5 Fl Oz) | Intensive Moisturizer Enriched with Vitamin E to | D63: 4.8 | E63: 44127 | F63: 6.69 | G63: USD | I63: https://www.amazon.com/Palmers-Butter-Formula-Therapy-Moisturization/dp/B0009F3O8Q/ref=zg_bs_g_11060661_d_sccl_11/136-1893143-0116527
A64: 62 | B64: B0CXF7PXCF | C64: Naturium The Glow Getter Multi-Oil Body Butter, 7.7 fl oz | Nourishing Whipped Moisturizer, Oil Infused Formula with Shea But | D64: 4.4 | E64: 2985 | F64: 17.88 | G64: USD | I64: https://www.amazon.com/Naturium-Whipped-Multi-Oil-Firming-Moisturizer/dp/B0CXF7PXCF/ref=zg_bs_g_11060661_d_sccl_12/136-1893143-0116527
...

Sheet Face
A1: Amazon Best Sellers — Face | I1: 🔗 Best Sellers 페이지 열기
A2: rank | B2: asin | C2: title | D2: rating | E2: ratings_count | F2: price | G2: currency | H2: offers_text | I2: url
A3: 1 | B3: B09V7Z4TJG | C3: medicube Toner Pads Zero Pore Pad 2.0 for Exfoliation and Pore Care | Dual-Textured Facial Pad with 4.5% AHA Lactic Acid, 0.4 | D3: 4.6 | E3: 30722 | F3: 15.12 | G3: USD | I3: https://www.amazon.com/Medicube-Zero-Pore-Pads-Dual-Textured/dp/B09V7Z4TJG/ref=zg_bs_g_11060711_d_sccl_1/136-1893143-0116527
A4: 2 | B4: B07PBXXNCY | C4: Clean Skin Club Clean Towels XL®, 100% USDA Biobased Face Towel, Disposable Face Towelette, Eczema Association Accepted, Make | D4: 4.7 | E4: 51792 | F4: 17.95 | G4: USD | I4: https://www.amazon.com/Clean-Skin-Club-Disposable-Sensitive/dp/B07PBXXNCY/ref=zg_bs_g_11060711_d_sccl_2/136-1893143-0116527
A5: 3 | B5: B074PVTPBW | C5: Mighty Patch Hero Cosmetics Original Nighttime Acne Pimple Patches, 36 Ct | #1 Hydrocolloid Acne Patches, Shrinking Zits & Wh | D5: 4.6 | E5: 184770 | F5: 12.99 | G5: USD | I5: https://www.amazon.com/Mighty-Patch-Hydrocolloid-Absorbing-count/dp/B074PVTPBW/ref=zg_bs_g_11060711_d_sccl_3/136-1893143-0116527
A6: 4 | B6: B00U2VQZDS | C6: Neutrogena Makeup Remover Micellar Wipes, 2 Pack of 25 Ct | Plant-Based Micellar Water Cleansing Cloths, Gently Removes Oil, | D6: 4.8 | E6: 121294 | F6: 9.97 | G6: USD | I6: https://www.amazon.com/Neutrogena-Makeup-Remover-Micellar-Wipes/dp/B00U2VQZDS/ref=zg_bs_g_11060711_d_sccl_4/136-1893143-0116527
A7: 5 | B7: B071914GGL | C7: The Ordinary Glycolic Acid 7% Exfoliating Toner, Brightening and Smoothing Daily Toner for More Even-Looking Skin Tone | D7: 4.7 | E7: 61699 | F7: 13.5 | G7: USD | I7: https://www.amazon.com/Ordinary-Exfoliating-Brightening-Smoothing-Even-Looking/dp/B071914GGL/ref=zg_bs_g_11060711_d_sccl_5/136-1893143-0116527
A8: 6 | B8: B081KL2QYJ | C8: PanOxyl 10% Benzoyl Peroxide Acne Foaming Wash, Maximum Strength, Daily Acne-Fighting Face and Body Cleanser, Face Wash to Cl | D8: 4.6 | E8: 82880 | F8: 10.19 | G8: USD | I8: https://www.amazon.com/PanOxyl-Foaming-Peroxide-Strength-Antimicrobial/dp/B081KL2QYJ/ref=zg_bs_g_11060711_d_sccl_6/136-1893143-0116527
A9: 7 | B9: B0B2RM68G2 | C9: BIODANCE Bio-Collagen Real Deep Mask, Hydrating Overnight Hydrogel Face Mask, Pore Minimizing, Elasticity, Plumping, Travel E | D9: 4.5 | E9: 46170 | F9: 19 | G9: USD | I9: https://www.amazon.com/Biodance-Bio-Collagen-Tightening-Hydrating-Molecular/dp/B0B2RM68G2/ref=zg_bs_g_11060711_d_sccl_7/136-1893143-0116527
A10: 8 | B10: B0DGPSZVW3 | C10: medicube Jelly Cream with Collagen & Niacinamide, 1.69 fl.oz | Freeze-Dried Hydrolyzed Collagen for Skin Barrier Hydration, 2 | D10: 4.5 | E10: 35843 | F10: 9.9 | G10: USD | I10: https://www.amazon.com/medicube-Collagen-Niacinamide-Freeze-Dried-Hydrolyzed/dp/B0DGPSZVW3/ref=zg_bs_g_11060711_d_sccl_8/136-1893143-0116527
A11: 9 | B11: B08BW46XXK | C11: Vanicream Daily Facial Moisturizer, Lightweight, Non-Greasy, 3 Fl Oz | Formulated Without Common Irritants for Sensitive Skin | D11: 4.6 | E11: 25513 | F11: 13.97 | G11: USD | I11: https://www.amazon.com/Vanicream-Moisturizer-Hyaluronic-pH-Balanced-Dermatologist/dp/B08BW46XXK/ref=zg_bs_g_11060711_d_sccl_9/136-1893143-0116527
A12: 10 | B12: B0DBF65JYY | C12: medicube PDRN Pink Peptide Serum with Salmon DNA | Pink Glow Serum - Peptides & Niacinamide for Hydration & Firm-Looking Skin | D12: 4.6 | E12: 21102 | F12: 15.12 | G12: USD | I12: https://www.amazon.com/medicube-Niacinamide-Hydrating-Moisturizing-Skincare/dp/B0DBF65JYY/ref=zg_bs_g_11060711_d_sccl_10/136-1893143-0116527
A13: 11 | B13: B0DYTQ5GYQ | C13: medicube Facial Cleanser Zero Pore Capsule Cleansing Foam | Daily Gentle Cleanser for Skin Texture, Blackhead & Pore Care - A | D13: 4.6 | E13: 3810 | F13: 12.9 | G13: USD | I13: https://www.amazon.com/medicube-Cleanser-Blackhead-Cleansing-Skincare/dp/B0DYTQ5GYQ/ref=zg_bs_g_11060711_d_sccl_11/136-1893143-0116527
A14: 12 | B14: B01N9SPQHQ | C14: La Roche-Posay Toleriane Double Repair Face Moisturizer | D14: 4.6 | E14: 51318 | F14: 24.99 | G14: USD | I14: https://www.amazon.com/Roche-Posay-Toleriane-Double-Repair-Moisturizer/dp/B01N9SPQHQ/ref=zg_bs_g_11060711_d_sccl_12/136-1893143-0116527
... A32: 30 | B32: B01N7T7JKJ | C32: La Roche-Posay Toleriane Hydrating Gentle Facial Cleanser, with Niacinamide | Face cleanser with niacinamide & ceramides, saf | D32: 4.6 | E32: 39523 | F32: 19.99 | G32: USD | I32: https://www.amazon.com/Roche-Posay-Toleriane-Hydrating-Gentle-Cleanser/dp/B01N7T7JKJ/ref=zg_bs_g_11060711_d_sccl_30/136-1893143-0116527
A33: 31 | B33: B0DK4Y2YP3
A34: 32 | B34: B0DG1DQ2S7
A35: 33 | B35: B0GVQ6NYR3
A36: 34 | B36: B00SNPCSUY
A37: 35 | B37: B0BFQ9RD5B
A38: 36 | B38: B0DFY92NDB
A39: 37 | B39: B0FVT77ZLL
A40: 38 | B40: B0BBSP2JNQ
A41: 39 | B41: B0D8W1YVBX
A42: 40 | B42: B0C3PCJ6SD
A43: 41 | B43: B07VRFC3Y7
A44: 42 | B44: B07XC569XF
... A52: 50 | B52: B01M4NFD2N
A53: 51 | B53: B0FPQGLYK9 | C53: medicube Sunscreen No Cast Just Glow Collagen, SPF 50 | SPF 50 Hydrating Face Sunscreen - Lightweight & Non-Sticky Formula, P | D53: 4.6 | E53: 2456 | F53: 13 | G53: USD | I53: https://www.amazon.com/medicube-Sunscreen-Lightweight-Non-Sticky-Hydrating/dp/B0FPQGLYK9/ref=zg_bs_g_11060711_d_sccl_1/136-1893143-0116527
A54: 52 | B54: B0C7JJG6BB | C54: CeraVe Acne Control Cleanser, Face Wash with 2% Salicylic Acid, 16 oz | Skin Care with Niacinamide, Acne Face Wash, Acne Trea | D54: 4.7 | E54: 23339 | F54: 17.24 | G54: USD | I54: https://www.amazon.com/CeraVe-Treatment-Salicylic-Purifying-Comedogenic/dp/B0C7JJG6BB/ref=zg_bs_g_11060711_d_sccl_2/136-1893143-0116527
A55: 53 | B55: B07VWSN95S | C55: CeraVe Resurfacing Retinol Face Serum with Niacinamide, Pore Minimizer, 1oz | Skin Care Brightening Serum with Licorice Root, | D55: 4.6 | E55: 56795 | F55: 16.49 | G55: USD | I55: https://www.amazon.com/CeraVe-Post-Acne-Refining-Resurfacing-Brightening/dp/B07VWSN95S/ref=zg_bs_g_11060711_d_sccl_3/136-1893143-0116527
A56: 54 | B56: B01EKUBU5Y | C56: TruSkin Brightening Vitamin C Serum for Face with Hyaluronic Acid, 2 fl oz | Anti aging face serum with Vitamin E to improve | D56: 4.4 | E56: 156495 | F56: 21.4 | G56: USD | I56: https://www.amazon.com/TruSkin-Naturals-Vitamin-Topical-Hyaluronic/dp/B01EKUBU5Y/ref=zg_bs_g_11060711_d_sccl_4/136-1893143-0116527
A57: 55 | B57: B01NCWV3KM | C57: La Roche-Posay Toleriane Double Repair UV SPF 30 Face Moisturizer | D57: 4.6 | E57: 29245 | F57: 24.99 | G57: USD | I57: https://www.amazon.com/Roche-Posay-Toleriane-Double-Repair-Moisturizer/dp/B01NCWV3KM/ref=zg_bs_g_11060711_d_sccl_5/136-1893143-0116527
A58: 56 | B58: B00PBX3L7K | C58: COSRX Snail Mucin 96% Repairing Serum for Sooothing & Hydrating 3.38 oz. | Snail Secretion Filtrate for Dull Skin & Fine Line | D58: 4.6 | E58: 106249 | F58: 18.5 | G58: USD | I58: https://www.amazon.com/COSRX-Repairing-Hydrating-Secretion-Phthalates/dp/B00PBX3L7K/ref=zg_bs_g_11060711_d_sccl_6/136-1893143-0116527
A59: 57 | B59: B0D16L5F2M | C59: medicube Exosome Shot Zero 2,000 PPM Spicule Facial Serum | Liquid Skin Booster Serum with Exosome, AHA+BHA+PHA - Pore Care, | D59: 4.5 | E59: 3794 | F59: 12.99 | G59: USD | I59: https://www.amazon.com/Medicube-Exosome-Spicule-Booster-Texture/dp/B0D16L5F2M/ref=zg_bs_g_11060711_d_sccl_7/136-1893143-0116527
A60: 58 | B60: B0BPXT3GBN | C60: medicube Triple Collagen Cream for Hydrating & Firming | Moisturizer with Hyaluronic Acid, Premium Elastin, Shea Butter - Wri | D60: 4.6 | E60: 10271 | F60: 15.84 | G60: USD | I60: https://www.amazon.com/Medicube-Triple-Collagen-Cream-Moisturizer/dp/B0BPXT3GBN/ref=zg_bs_g_11060711_d_sccl_8/136-1893143-0116527
A61: 59 | B61: B081KLNHSG | C61: PanOxyl Antimicrobial Acne Creamy Wash, 4% Benzoyl Peroxide, 6 Ounce | Dermatologist-Recommended, Antibacterial Daily Cleanse | D61: 4.6 | E61: 17726 | F61: 10.19 | G61: USD | I61: https://www.amazon.com/PanOxyl-Benzoyl-Peroxide-Control-Antimicrobial/dp/B081KLNHSG/ref=zg_bs_g_11060711_d_sccl_9/136-1893143-0116527
A62: 60 | B62: B0DC156Y5X | C62: JIYU Toner Pads - Korean Skincare for Dark Spots, Wrinkles & Dull Skin - Hydrating Facial Treatment with Snail Mucin, Niacina | D62: 4.3 | E62: 5174 | F62: 43.99 | G62: USD | I62: https://www.amazon.com/Toning-Polish-Pads-Hydrating-Niacinamide/dp/B0DC156Y5X/ref=zg_bs_g_11060711_d_sccl_10/136-1893143-0116527
A63: 61 | B63: B0B3SCM1L6 | C63: Tower 28 SOS Daily Rescue Soothing Hypochlorous Acid Spray for Face (1 oz) | Hypochlorous Acid Face Mist to Calm & Purify Sen | D63: 4.6 | E63: 5332 | F63: 12 | G63: USD | I63: https://www.amazon.com/Tower-28-Beauty-Rescue-Facial/dp/B0B3SCM1L6/ref=zg_bs_g_11060711_d_sccl_11/136-1893143-0116527
A64: 62 | B64: B08TM8DLFJ | C64: Good Molecules Hyaluronic Acid Serum for Face, Hydrating Serum, 1 fl oz | Deeply hydrates to plump the look of fine lines. Bo | D64: 4.7 | E64: 17618 | F64: 5.97 | G64: USD | I64: https://www.amazon.com/Good-Molecules-Hyaluronic-Long-Lasting-Fragrance-free/dp/B08TM8DLFJ/ref=zg_bs_g_11060711_d_sccl_12/136-1893143-0116527
...

Sheet Eyes
A1: Amazon Best Sellers — Eyes | I1: 🔗 Best Sellers 페이지 열기
A2: rank | B2: asin | C2: title | D2: rating | E2: ratings_count | F2: price | G2: currency | H2: offers_text | I2: url
A3: 1 | B3: B0GHMZXX8Y | C3: medicube PDRN Pink Collagen Volume Multi Balm Stick - Face & Body Balm | Volufiline, PDRN, NAD, Collagen - Under-Eyes, Neck, | D3: 3.8 | E3: 2423 | F3: 15.2 | G3: USD | I3: https://www.amazon.com/medicube-Collagen-Volufiline-Under-Eyes-Forehead/dp/B0GHMZXX8Y/ref=zg_bs_g_11061941_d_sccl_1/136-1893143-0116527
A4: 2 | B4: B0GD6R7CFJ | C4: BIODANCE Hydrogel Eye Patches for Under Eye - Collagen Peptide, Anti Wrinkle & Fine Lines (60 Count) | D4: 4.5 | E4: 3558 | F4: 23 | G4: USD | I4: https://www.amazon.com/BIODANCE-Collagen-Peptide-Patches-Essentials/dp/B0GD6R7CFJ/ref=zg_bs_g_11061941_d_sccl_2/136-1893143-0116527
A5: 3 | B5: B014E2D6BY | C5: grace & stella Award Winning Eye Patches for Puffy Eyes | Birthday Gifts for Women - Under Eye Mask for Dark Circles & Undere | D5: 4.3 | E5: 49117 | F5: 23.95 | G5: USD | I5: https://www.amazon.com/Under-Eye-Patches-Gold-24-Pairs/dp/B014E2D6BY/ref=zg_bs_g_11061941_d_sccl_3/136-1893143-0116527
A6: 4 | B6: B0G38FGSKL | C6: medicube Eye Patch PDRN Caffeine Collagen - Firming Gel Patches, | Age-Defying Care with Retinol & Collagen - Gel Patches for | D6: 4.4 | E6: 982 | F6: 16.9 | G6: USD | I6: https://www.amazon.com/medicube-Caffeine-Collagen-appearance-Age-Defying/dp/B0G38FGSKL/ref=zg_bs_g_11061941_d_sccl_4/136-1893143-0116527
A7: 5 | B7: B0DWMSM6Y9 | C7: medicube Eye Serum with Salmon DNA PDRN & Pink Peptides | 99% Purity Retinol for Fine Lines - PDRN & Niacinamide for Uneven S | D7: 4.5 | E7: 5832 | F7: 15.12 | G7: USD | I7: https://www.amazon.com/medicube-Serum-Salmon-PDRN-Peptides/dp/B0DWMSM6Y9/ref=zg_bs_g_11061941_d_sccl_5/136-1893143-0116527
A8: 6 | B8: B091NJQ29P | C8: Good Molecules Yerba Mate Wake Up Eye Gel, Caffeine Under Eye Cream, 15 ml | Refreshes and hydrates tired under eyes with caf | D8: 4.2 | E8: 33344 | F8: 5.97 | G8: USD | I8: https://www.amazon.com/Good-Molecules-Formulated-Revitalize-Fragrance/dp/B091NJQ29P/ref=zg_bs_g_11061941_d_sccl_6/136-1893143-0116527
A9: 7 | B9: B0GHNDWQFN | C9: medicube Jelly Eye Mask PDRN Pink Collagen - Hydrogel Eye Patches, 6 Pairs | Eye Patches with PDRN, Collagen, NAD - For Puffy | D9: 4.4 | E9: 355 | F9: 8.9 | G9: USD | I9: https://www.amazon.com/medicube-Collagen-Hydrogel-Refreshing-Wrinkles/dp/B0GHNDWQFN/ref=zg_bs_g_11061941_d_sccl_7/136-1893143-0116527
A10: 8 | B10: B0CNCL35CH | C10: Dr.Melaxin Collagen Multi Balm Stick, Calcium & Adenosine Korean Wrinkle Stick for Eye, Neck & Face, Firming Collagen Stick, | D10: 4.1 | E10: 9647 | F10: 19 | G10: USD | I10: https://www.amazon.com/Dr-Melaxin-Cemenrete-Collagen-Wrinkles-treatment/dp/B0CNCL35CH/ref=zg_bs_g_11061941_d_sccl_8/136-1893143-0116527
A11: 9 | B11: B0B3GCCRVH | C11: CeraVe Eye Cream for Wrinkles with Peptides, Caffeine & Niacinamide, 0.5oz | Dermatologist-Tested Skin Care Formula Targets C | D11: 4.5 | E11: 9440 | I11: https://www.amazon.com/CeraVe-Hyaluronic-Niacinamide-Ceramides-Ophthalmologist/dp/B0B3GCCRVH/ref=zg_bs_g_11061941_d_sccl_9/136-1893143-0116527
A12: 10 | B12: B01MUZVE1C | C12: The Ordinary Caffeine Solution 5% + EGCG Eye Serum, Depuffing Eye Serum for Dark Circles and Tired Eyes | D12: 4.4 | E12: 18976 | F12: 9.2 | G12: USD | I12: https://www.amazon.com/Ordinary-Caffeine-Solution-EGCG-30ml/dp/B01MUZVE1C/ref=zg_bs_g_11061941_d_sccl_10/136-1893143-0116527
A13: 11 | B13: B0B45LL4DD | C13: Beauty of Joseon Revive Eye Serum with Retinal Niacinamide Correction for Puffy Eye Bags Fine Lines Dark Circles Wrinkles, Ko | D13: 4.3 | E13: 20616 | F13: 17 | G13: USD | I13: https://www.amazon.com/Beauty-Joseon-Revive-eye-serum/dp/B0B45LL4DD/ref=zg_bs_g_11061941_d_sccl_11/136-1893143-0116527
A14: 12 | B14: B0B5DYY1HQ | C14: The Ordinary Multi-Peptide Lash and Brow Serum, Peptide-Powered Formula for Thicker, Fuller Looking Lashes & Brows | D14: 4.2 | E14: 6886 | F14: 14.9 | G14: USD | I14: https://www.amazon.com/Ordinary-Multi-Peptide-Lash-Brow-Serum/dp/B0B5DYY1HQ/ref=zg_bs_g_11061941_d_sccl_12/136-1893143-0116527
A15: 13 | B15: B01CVXSPBO | C15: Abib Vegan Collagen Eye Patches for Wrinkles & Fine Line with Jericho Rose Jelly & Peptides, 60 Count, Korean Skin Care | D15: 4.6 | E15: 3566 | F15: 17.96 | G15: USD | I15: https://www.amazon.com/Collagen-Peptide-Patches-Wrinkles-Jericho/dp/B01CVXSPBO/ref=zg_bs_g_11061941_d_sccl_13/136-1893143-0116527
A16: 14 | B16: B00JJPMXDO | C16: CeraVe Eye Repair Cream, Hyaluronic Acid Eye Cream for Dark Circles, 0.5oz | Skin Care, Under Eye Treatment for Puffiness wit | D16: 4.3 | E16: 75321 | F16: 14.44 | G16: USD | I16: https://www.amazon.com/CeraVe-Repair-Cream-Circles-Puffiness/dp/B00JJPMXDO/ref=zg_bs_g_11061941_d_sccl_14/136-1893143-0116527
A17: 15 | B17: B0C9F5GMF2 | C17: OCuSOFT Lid Scrub Plus Inflation Buster, Pre-Moistened Pads, 30+5 Count | Designed for eyelids exposed to environmental irrit | D17: 4.7 | E17: 5375 | F17: 19.95 | G17: USD | I17: https://www.amazon.com/OCuSOFT-Scrub-Count-Inflation-Buster/dp/B0C9F5GMF2/ref=zg_bs_g_11061941_d_sccl_15/136-1893143-0116527
A18: 16 | B18: B00027DMSI | C18: Frownies Forehead & Between the Eyes Wrinkle Patches, 144 Count | Overnight Patches for Forehead & 11 Lines | D18: 3.8 | E18: 41241 | F18: 25.95 | G18: USD | I18: https://www.amazon.com/Frownies-Forehead-Between-Eyes-Patches/dp/B00027DMSI/ref=zg_bs_g_11061941_d_sccl_16/136-1893143-0116527
A19: 17 | B19: B0BS8Y2FLK | C19: PEAUAMIE Under Eye Patches Gold and Hyaluronic Acid for puffy eyes,Rose Eye Masks for Dark Circles and Puffiness skin care Sm | D19: 4.4 | E19: 11107 | F19: 9.99 | G19: USD | I19: https://www.amazon.com/PEAUAMIE-Hyaluronic-Puffiness-treatment-products/dp/B0BS8Y2FLK/ref=zg_bs_g_11061941_d_sccl_17/136-1893143-0116527
A20: 18 | B20: B0009RFB76 | C20: RoC Retinol Correxion Under Eye Cream for Dark Circles & Puffiness, 0.50z | Anti-Aging Retinol Eye Treatment, Clinically Prov | D20: 4.3 | E20: 34240 | F20: 21.97 | G20: USD | I20: https://www.amazon.com/RoC-Correxion-Anti-Aging-Treatment-Puffiness/dp/B0009RFB76/ref=zg_bs_g_11061941_d_sccl_18/136-1893143-0116527
A21: 19 | B21: B0BDDJGXDY | C21: Maskiss 24k Gold Under Eye Patches (50 Pairs), eye mask, Collagen Skin Care Products, Eye Patches for Puffy Eyes, eye masks f | D21: 4.4 | E21: 14269 | F21: 26.95 | G21: USD | I21: https://www.amazon.com/Maskiss-50-Pairs-Puffiness-Collagen-Products/dp/B0BDDJGXDY/ref=zg_bs_g_11061941_d_sccl_19/136-1893143-0116527
A22: 20 | B22: B09SZ5JX2Y | C22: d'alba Piedmont White Truffle Double Serum All-in-one Multi Balm (0.35 oz) | Stick Balm, Under Eye Makeup Prep, Wrinkle Care, | D22: 4.5 | E22: 8596 | F22: 14.16 | G22: USD | I22: https://www.amazon.com/dalba-Piedmont-White-Truffle-Double/dp/B09SZ5JX2Y/ref=zg_bs_g_11061941_d_sccl_20/136-1893143-0116527
A23: 21 | B23: B0F19YY96Z | C23: Summer Fridays Jet Lag Hydrating Eye Patches - De-puffing Hydrogel Under Eye Masks with Hyaluronic Acid, Caffeine + Peptides | D23: 4.6 | E23: 612 | F23: 24 | G23: USD | I23: https://www.amazon.com/Summer-Fridays-Jet-Under-Patches/dp/B0F19YY96Z/ref=zg_bs_g_11061941_d_sccl_21/136-1893143-0116527
... A32: 30 | B32: B0D4Q8SR9Z | C32: MEDIHEAL 95% Retinol & Collagen Under Eye Patches, Wrinkle Care (60 Count) | with Retinol Liposome, Collagen | 4-Zone Firming | D32: 4.3 | E32: 1927 | F32: 13.8 | G32: USD | I32: https://www.amazon.com/Mediheal-Retinol-Collagen-Under-Patches/dp/B0D4Q8SR9Z/ref=zg_bs_g_11061941_d_sccl_30/136-1893143-0116527
A33: 31 | B33: B0CHXDKRR6
A34: 32 | B34: B0C4NWGVTF
A35: 33 | B35: B0CRXHWR48
A36: 34 | B36: B07Q1DVG7S
A37: 35 | B37: B08DG3C22G
A38: 36 | B38: B0FC5W77MB
A39: 37 | B39: B0CC6PG567
A40: 38 | B40: B0D2QP4H4K
A41: 39 | B41: B0FB5YDC23
A42: 40 | B42: B0GL3BB3V5
A43: 41 | B43: B0BV6YFW33
A44: 42 | B44: B0CYKRBVWC
... A52: 50 | B52: B07BYG7D2V
A53: 51 | B53: B004Y9GTYE | C53: Maybelline Instant Age Rewind Eraser Dark Circles Treatment Multi-Use Concealer, 120, 1 Count (Packaging May Vary) | D53: 4.4 | E53: 246109 | F53: 9.98 | G53: USD | I53: https://www.amazon.com/Maybelline-Instant-Circles-Treatment-Concealer/dp/B004Y9GTYE/ref=zg_bs_g_11061941_d_sccl_1/136-1893143-0116527
A54: 52 | B54: B0FHH37MZJ | C54: Beauty of Joseon Revive Under Eye Patch with Retinal and Ginseng, for Puffy Eyes, Fine Lines and Wrinkles, Collagen, Peptide, | D54: 4.3 | E54: 1151 | F54: 20 | G54: USD | I54: https://www.amazon.com/Beauty-Joseon-Retinal-Collagen-Skincare/dp/B0FHH37MZJ/ref=zg_bs_g_11061941_d_sccl_2/136-1893143-0116527
A55: 53 | B55: B0BLHFPFV9 | C55: Enaskin Naturals Under Eye Patches for Puffy Eyes & Dark Circles 60 Patches | Each Gel Patch Delivers Retinol and Collagen to | D55: 4.3 | E55: 4761 | F55: 16.99 | G55: USD | I55: https://www.amazon.com/Enaskin-Naturals-Patches-Treatment-Wrinkles/dp/B0BLHFPFV9/ref=zg_bs_g_11061941_d_sccl_3/136-1893143-0116527
...

Sheet Sunscreens
A1: Amazon Best Sellers — Sunscreens | I1: 🔗 Best Sellers 페이지 열기
A2: rank | B2: asin | C2: title | D2: rating | E2: ratings_count | F2: price | G2: currency | H2: offers_text | I2: url
A3: 1 | B3: B002MSN3QQ | C3: EltaMD UV Clear Face Sunscreen with Zinc Oxide, Oil-Free, SPF 46 and SPF 50 | Calms and Protects Acne-Prone Skin and Rosacea, | D3: 4.5 | E3: 70565 | F3: 45 | G3: USD | I3: https://www.amazon.com/EltaMD-Clear-Untinted-Sunscreen-Oxide/dp/B002MSN3QQ/ref=zg_bs_g_11062651_d_sccl_1/136-1893143-0116527
A4: 2 | B4: B084ZP848Y | C4: Blue Lizard Sensitive Mineral SPF 50 Sunscreen Lotion, 100% Mineral Sunscreen, UVA/UVB Protection, Infused with organic Aloe | D4: 4.4 | E4: 21370 | F4: 15.48 | G4: USD | I4: https://www.amazon.com/Blue-Lizard-Sensitive-Mineral-Sunscreen/dp/B084ZP848Y/ref=zg_bs_g_11062651_d_sccl_2/136-1893143-0116527
A5: 3 | B5: B00J5KDCO2 | C5: EltaMD UV Daily Face Sunscreen Moisturizer, Zinc Oxide, SPF 40 and SPF 50 | Hydrates and Protects Dry Dehydrated Skin, Lightw | D5: 4.6 | E5: 44771 | F5: 43 | G5: USD | I5: https://www.amazon.com/EltaMD-Moisturizer-Hyaluronic-Mineral-Based-Protection/dp/B00J5KDCO2/ref=zg_bs_g_11062651_d_sccl_3/136-1893143-0116527
A6: 4 | B6: B0FPQGLYK9 | C6: medicube Sunscreen No Cast Just Glow Collagen, SPF 50 | SPF 50 Hydrating Face Sunscreen - Lightweight & Non-Sticky Formula, P | D6: 4.6 | E6: 2456 | F6: 13 | G6: USD | I6: https://www.amazon.com/medicube-Sunscreen-Lightweight-Non-Sticky-Hydrating/dp/B0FPQGLYK9/ref=zg_bs_g_11062651_d_sccl_4/136-1893143-0116527
A7: 5 | B7: B07YLKXV11 | C7: CeraVe Tinted Sunscreen for Face, Mineral SPF 30 Moisturizer, Medium, 1.7oz | Skin Care, Face Sunscreen, Hyaluronic Acid, Zin | D7: 4.4 | E7: 73440 | F7: 13.97 | G7: USD | I7: https://www.amazon.com/CeraVe-Sunscreen-Hydrating-Mineral-Titanium/dp/B07YLKXV11/ref=zg_bs_g_11062651_d_sccl_5/136-1893143-0116527
A8: 6 | B8: B01MQXX9US | C8: Banana Boat Sport SPF 50 Sunscreen Spray, 6 oz (2 Pack) | Sweat and water resistant sunblock spray, UVA/UVB broad spectrum pr | D8: 4.8 | E8: 26608 | F8: 13.86 | G8: USD | I8: https://www.amazon.com/Banana-Boat-Sunscreen-Performance-Spectrum/dp/B01MQXX9US/ref=zg_bs_g_11062651_d_sccl_6/136-1893143-0116527
A9: 7 | B9: B005IHT94S | C9: Neutrogena Ultra Sheer Dry Touch Sunscreen Lotion, SPF 70, 3 fl. oz | Broad Spectrum for UVA/UVB Protection, Lightweight, Wat | D9: 4.5 | E9: 39925 | F9: 9.88 | G9: USD | I9: https://www.amazon.com/Neutrogena-Ultra-Dry-Touch-Sunscreen-Spectrum/dp/B005IHT94S/ref=zg_bs_g_11062651_d_sccl_7/136-1893143-0116527
